同步的订单信息:{"external_id":"951","name":"20190606288031","date_order":"2019-06-06","state":"done","order_type":"tech_order","return_process":"False","amount_paid":"100.00","amount_return":0,"branch_name":"\u95e8\u5e971\u5e97\u94fa","branch_phone":"13838383838","lines":[[0,"2095",{"external_id":"2095","name":"\u95e8\u5e971\u5546\u54c11","attribute":"\u5bb6\u5c45:\u7d2b\u8d28\u51c0\u5316\u7115\u989c\u5957","price_unit":"100.00","line_note":"\u6280\u5e08\u7aef\u8ba2\u5355"}]]}
同步的订单结果:{"faultCode":1,"faultString":"Traceback (most recent call last):\n  File \"\/opt\/odoo\/odoo\/odoo\/addons\/base\/controllers\/rpc.py\", line 63, in xmlrpc_2\n    response = self._xmlrpc(service)\n  File \"\/opt\/odoo\/odoo\/odoo\/addons\/base\/controllers\/rpc.py\", line 43, in _xmlrpc\n    result = dispatch_rpc(service, method, params)\n  File \"\/opt\/odoo\/odoo\/odoo\/http.py\", line 120, in dispatch_rpc\n    result = dispatch(method, params)\n  File \"\/opt\/odoo\/odoo\/odoo\/service\/model.py\", line 39, in dispatch\n    res = fn(db, uid, *params)\n  File \"\/opt\/odoo\/odoo\/odoo\/service\/model.py\", line 153, in execute_kw\n    return execute(db, uid, obj, method, *args, **kw or {})\n  File \"\/opt\/odoo\/odoo\/odoo\/service\/model.py\", line 97, in wrapper\n    return f(dbname, *args, **kwargs)\n  File \"\/opt\/odoo\/odoo\/odoo\/service\/model.py\", line 160, in execute\n    res = execute_cr(cr, uid, obj, method, *args, **kw)\n  File \"\/opt\/odoo\/odoo\/odoo\/service\/model.py\", line 149, in execute_cr\n    return odoo.api.call_kw(recs, method, args, kw)\n  File \"\/opt\/odoo\/odoo\/odoo\/api.py\", line 745, in call_kw\n    return _call_kw_model(method, model, args, kwargs)\n  File \"\/opt\/odoo\/odoo\/odoo\/api.py\", line 718, in _call_kw_model\n    result = method(recs, *args, **kwargs)\n  File \"\/opt\/odoo\/spa-pos\/addons\/pos_commission\/models\/pos_order.py\", line 264, in sync_pos_order\n    raise Exception(_(u'\u5546\u54c1\u540d\u79f0\u683c\u5f0f\u4e0d\u6b63\u786e,\u6280\u5e08-\u6280\u5e08\u7f16\u53f7-\u670d\u52a1\u540d\u79f0'))\nException: \u5546\u54c1\u540d\u79f0\u683c\u5f0f\u4e0d\u6b63\u786e,\u6280\u5e08-\u6280\u5e08\u7f16\u53f7-\u670d\u52a1\u540d\u79f0\n"}
同步的订单信息:{"external_id":"951","name":"20190606288031","date_order":"2019-06-06","state":"done","order_type":"tech_order","return_process":"False","amount_paid":"100.00","amount_return":0,"branch_name":"\u95e8\u5e971\u5e97\u94fa","branch_phone":"13838383838","technican_name":"\u6280\u5e08\u674e","technican_sn":"0002","lines":[[0,"2095",{"external_id":"2095","name":"\u95e8\u5e971\u5546\u54c11","attribute":"\u5bb6\u5c45:\u7d2b\u8d28\u51c0\u5316\u7115\u989c\u5957","price_unit":"100.00","line_note":"\u6280\u5e08\u7aef\u8ba2\u5355"}]]}
同步的订单结果:{"faultCode":1,"faultString":"Traceback (most recent call last):\n  File \"\/opt\/odoo\/odoo\/odoo\/addons\/base\/controllers\/rpc.py\", line 63, in xmlrpc_2\n    response = self._xmlrpc(service)\n  File \"\/opt\/odoo\/odoo\/odoo\/addons\/base\/controllers\/rpc.py\", line 43, in _xmlrpc\n    result = dispatch_rpc(service, method, params)\n  File \"\/opt\/odoo\/odoo\/odoo\/http.py\", line 120, in dispatch_rpc\n    result = dispatch(method, params)\n  File \"\/opt\/odoo\/odoo\/odoo\/service\/model.py\", line 39, in dispatch\n    res = fn(db, uid, *params)\n  File \"\/opt\/odoo\/odoo\/odoo\/service\/model.py\", line 153, in execute_kw\n    return execute(db, uid, obj, method, *args, **kw or {})\n  File \"\/opt\/odoo\/odoo\/odoo\/service\/model.py\", line 97, in wrapper\n    return f(dbname, *args, **kwargs)\n  File \"\/opt\/odoo\/odoo\/odoo\/service\/model.py\", line 160, in execute\n    res = execute_cr(cr, uid, obj, method, *args, **kw)\n  File \"\/opt\/odoo\/odoo\/odoo\/service\/model.py\", line 149, in execute_cr\n    return odoo.api.call_kw(recs, method, args, kw)\n  File \"\/opt\/odoo\/odoo\/odoo\/api.py\", line 745, in call_kw\n    return _call_kw_model(method, model, args, kwargs)\n  File \"\/opt\/odoo\/odoo\/odoo\/api.py\", line 718, in _call_kw_model\n    result = method(recs, *args, **kwargs)\n  File \"\/opt\/odoo\/spa-pos\/addons\/pos_commission\/models\/pos_order.py\", line 264, in sync_pos_order\n    raise Exception(_(u'\u5546\u54c1\u540d\u79f0\u683c\u5f0f\u4e0d\u6b63\u786e,\u6280\u5e08-\u6280\u5e08\u7f16\u53f7-\u670d\u52a1\u540d\u79f0'))\nException: \u5546\u54c1\u540d\u79f0\u683c\u5f0f\u4e0d\u6b63\u786e,\u6280\u5e08-\u6280\u5e08\u7f16\u53f7-\u670d\u52a1\u540d\u79f0\n"}
